<?xml version="1.0"?>
<robot name="beach_robot" xmlns:xacro="http://www.ros.org/wiki/xacro">

  <xacro:property name="chassis_length" value="0.60"/>
  <xacro:property name="chassis_width"  value="0.35"/>
  <xacro:property name="chassis_height" value="0.15"/>
  <xacro:property name="chassis_mass"   value="20.0"/>

  <xacro:property name="wheel_radius"    value="0.13"/>
  <xacro:property name="wheel_thickness" value="0.06"/>
  <xacro:property name="wheel_mass"      value="1.5"/>

  <xacro:property name="wheelbase_x" value="0.20"/>
  <xacro:property name="track_y"     value="${chassis_width/2 + wheel_thickness/2}"/>

  <xacro:macro name="box_inertia" params="m x y z">
    <inertial>
      <mass value="${m}"/>
      <inertia
        ixx="${m*(y*y+z*z)/12}" ixy="0" ixz="0"
        iyy="${m*(x*x+z*z)/12}" iyz="0"
        izz="${m*(x*x+y*y)/12}"/>
    </inertial>
  </xacro:macro>

  <xacro:macro name="cylinder_inertia" params="m r h">
    <inertial>
      <mass value="${m}"/>
      <inertia
        ixx="${m*(3*r*r+h*h)/12}" ixy="0" ixz="0"
        iyy="${m*(3*r*r+h*h)/12}" iyz="0"
        izz="${m*r*r/2}"/>
    </inertial>
  </xacro:macro>

  <xacro:macro name="wheel" params="name x y">
    <link name="${name}_link">
      <visual>
        <origin xyz="0 0 0" rpy="${pi/2} 0 0"/>
        <geometry>
          <cylinder radius="${wheel_radius}" length="${wheel_thickness}"/>
        </geometry>
        <material name="black"><color rgba="0.1 0.1 0.1 1"/></material>
      </visual>
      <collision>
        <origin xyz="0 0 0" rpy="${pi/2} 0 0"/>
        <geometry>
          <cylinder radius="${wheel_radius}" length="${wheel_thickness}"/>
        </geometry>
      </collision>
      <xacro:cylinder_inertia m="${wheel_mass}" r="${wheel_radius}" h="${wheel_thickness}"/>
    </link>

    <joint name="${name}_joint" type="continuous">
      <parent link="base_link"/>
      <child link="${name}_link"/>
      <origin xyz="${x} ${y} 0" rpy="0 0 0"/>
      <axis xyz="0 1 0"/>
      <limit effort="100" velocity="20"/>
    </joint>
  </xacro:macro>

  <link name="base_footprint"/>

  <joint name="base_footprint_joint" type="fixed">
    <parent link="base_footprint"/>
    <child link="base_link"/>
    <origin xyz="0 0 ${wheel_radius}" rpy="0 0 0"/>
  </joint>

  <link name="base_link">
    <visual>
      <origin xyz="0 0 ${chassis_height/2}" rpy="0 0 0"/>
      <geometry>
        <box size="${chassis_length} ${chassis_width} ${chassis_height}"/>
      </geometry>
      <material name="orange"><color rgba="0.9 0.5 0.1 1"/></material>
    </visual>
    <collision>
      <origin xyz="0 0 ${chassis_height/2}" rpy="0 0 0"/>
      <geometry>
        <box size="${chassis_length} ${chassis_width} ${chassis_height}"/>
      </geometry>
    </collision>
    <xacro:box_inertia m="${chassis_mass}" x="${chassis_length}" y="${chassis_width}" z="${chassis_height}"/>
  </link>

  <xacro:wheel name="front_left"  x=" ${wheelbase_x}" y=" ${track_y}"/>
  <xacro:wheel name="front_right" x=" ${wheelbase_x}" y="-${track_y}"/>
  <xacro:wheel name="rear_left"   x="-${wheelbase_x}" y=" ${track_y}"/>
  <xacro:wheel name="rear_right"  x="-${wheelbase_x}" y="-${track_y}"/>

  <link name="imu_link">
    <xacro:box_inertia m="0.01" x="0.01" y="0.01" z="0.01"/>
  </link>
  <joint name="imu_joint" type="fixed">
    <parent link="base_link"/>
    <child link="imu_link"/>
    <origin xyz="0 0 ${chassis_height/2}" rpy="0 0 0"/>
  </joint>

  <link name="gps_link">
    <xacro:box_inertia m="0.01" x="0.01" y="0.01" z="0.01"/>
  </link>
  <joint name="gps_joint" type="fixed">
    <parent link="base_link"/>
    <child link="gps_link"/>
    <origin xyz="0 0 ${chassis_height+0.02}" rpy="0 0 0"/>
  </joint>

  <xacro:include filename="$(find beach_robot_description)/urdf/gazebo.xacro"/>

</robot>
